Workbook

Sheet Protocol
A1: LED Characterisation - Test Protocol
A2: Four LED types x three builds: bare LED (reference), 20 mm diffuser, 25 mm diffuser. Each diffused marker holds FOUR LEDs of the same type. Find the build with the lowest centroid noise.
A4: LEGEND
A5: Yellow fill = fill in while testing. Black = calculated. Bare rows are a reference only - they are not a marker and are not ranked.
A7: HOLD THESE CONSTANT FOR EVERY MEASUREMENT
A8: Parameter | B8: Value | C8: Note
A9: Date | B9: 46262
A10: Supply voltage (V) | B10: 9 | C10: one 9 V rail for every board: 4 LEDs in series + the series resistor
A11: Drive current (mA) | B11: set by the board resistor | C11: differs per part BY DESIGN - see the parts table below. Not a bench knob
A12: EXPOSURE_US | B12: varies per row | C12: a RESULT, not a constant. Quantised to ~21.3 us (one sensor row time), floor ~21 us
A13: Target peak | B13: 200 - 230 | C13: THE controlled variable. Background measured at max 4 counts, so the whole 0-255 range is signal
A14: GAIN_DB | B14: 0 | C14: keep at 0
A15: THRESH_LO | B15: 80 | C15: same for all tests
A16: REFINE_FLOOR | B16: 50 | C16: same for all tests
A17: Framesize / readout | B17: QVGA, 320×240, readout 320×240 -> Ratio 1:1 | C17: ratio must be 1:1
A18: Test A distance (m) | B18: 4 | C18: far end of the flight space - where the builds differ most. Test B uses the same distance
A19: Near limit, 0 deg (m) | B19: 2 | C19: closest a marker ever gets to a camera, square-on. Sets the exposure CEILING
A20: Ambient light | B20: Night test, lights in room on. | C20: e.g. blinds closed, lights off
A21: Camera / lens | B21: VL filter installend OpenMV RT1062 | C21: must not change between tests
A22: Build | B22: bare (ref) / 20 mm / 25 mm | C22: no diffuser fitted - all four LEDs lit, cap off
A24: BOARDS AND DRIVE CURRENT (from IR_LED_Parts_Calculator, 9 V, 4 in series, Vf 1.6 V each)
A25: Build | B25: Part | C25: R series (E12) | D25: I actual (mA)
A26: Vishay | B26: VSMY2850GX01 | C26: 33 | D26: 78.8
A27: Everlight | B27: HIR25-21C | C27: 68 | D27: 38.2
A28: XL | B28: XL-1608HIRC-850 | C28: 120 | D28: 21.7
A29: Kingbright | B29: Kingbright (different part, same 68 ohm / 38.2 mA operating point) | C29: 68 | D29: 38.2
A30: Vishay draws 2.1x Everlight and 3.6x XL. That is the design, not an error - but it is why Vishay clips first, so its brightness must be read as 'needs less exposure', not as 'saturates'.
A32: THE REGIME
A34: TEST A - Bench comparison (4 types x 3 builds = 12 rows)
A35: 1. Work one build at a time - the diffuser is the slow thing to change. All four types with the 20 mm, then all four with the 25 mm, then the bare reference LEDs.
A36: 2. Fix the marker at the Test A distance, facing the camera (0 deg).
A37: 3. MODE="expose" -> record Exposure, Peak, Sat px, Frames sat, blobs and w/h.
A38: 4. TARGET THE PEAK: if Peak is outside 200-230, take the 'Next exposure' the sheet computes, set it, and read again. Peak is linear in exposure while unclipped, so this converges in one or two goes.
A39: 5. If the row still clips at the exposure floor (~21 us), exposure has run out. Either move to the real operating range or add series resistance in-line - you can only ADD R, which lowers current, which is the direction a too-bright board needs.
A40: 6. BLEND GATE: blobs must read 1 and w/h must sit near 1.00. More than one blob means the four LEDs have not merged - every mode measures only the largest blob, so sigma would look fine while the marker is really four markers.
A41: 7. MODE="floor" -> record sigma_u, sigma_v, npix. Do NOT change REFINE_FLOOR between LEDs or between builds.
A42: 8. Only a row that is IN BAND, UNSATURATED and BLENDED carries a usable sigma. Everything else is a diagnostic, not a result.
A44: TEST B - Angular response and roll (each type x each build, at the Test A distance)
... A67: EXAMPLE ROW - this is the format expected on A_Bench:
A68: LED Type | B68: Build | C68: Sample | D68: Drive I | E68: Exposure | F68: Peak | G68: Sat px | H68: Area | I68: npix | J68: blobs | K68: w/h | L68: sigma_u | M68: sigma_v
...

Sheet A_Bench
A1: TEST A - Bench comparison at 4 m, 0 deg (run 4: reprinted caps, 4.5 s cure, blackout)
A2: Blue on yellow = fill in. Black = calculated. Peak targeted 205-215. BLEND GATE IS NOW fill >= 0.70, not 0.85: across 16 builds sigma improves with fill only up to ~0.65-0.70 and is flat above it (0.018-0.026 for every build, all four LEDs, against 10-15% repeatability). Above the knee you pay exposure for blending that buys no precision. Caps reprinted 4.5s cure, no supports, post-cured together. Focus locked, blackout, 4 m.
A3: LED Type | B3: Build | C3: Sample | D3: Distance (m) | E3: Drive I (mA) | F3: Exposure (us) | G3: Peak (0-255) | H3: Sat px | I3: Frames sat (of 200) | J3: Next exposure (us, aim 210) | K3: Sensor area (px) | L3: npix (refined) | M3: blobs (must be 1) | N3: w/h (want ~1.00) | O3: Blend gate | P3: sigma_u (px) | Q3: sigma_v (px) | R3: sigma_RMS (px) | S3: sig_v/sig_u (>3 = suspect) | T3: Notes | U3: Fill (centre/rim) | V3: Lobe (0=circular)
A4: EXAMPLE | B4: 20 mm | C4: 1 | E4: 38.2 | F4: 386 | G4: 218 | H4: 0 | I4: 0 | J4: =IF(OR(F4="",G4="",G4=0),"",IF(H4>0,"reduce light",ROUND(F4*210/G4/21.3,0)*21.3)) | K4: 984 | L4: 962 | M4: 1 | N4: 1.03 | O4: =IF(OR(M4="",N4="",U4=""),"",IF(AND(M4=1,N4>=0.9,N4<=1.1,U4>=0.70),"pass","FAIL")) | P4: 0.0298 | Q4: 0.0271 | R4: =IF(OR(P4="",Q4=""),"",SQRT(0.5*(P4^2+Q4^2))) | S4: =IF(OR(P4="",Q4="",P4=0),"",Q4/P4) | T4: peak in band, blend passes
A5: Vishay | B5: bare (ref) | C5: 1 | D5: 4 | E5: 78.8 | J5: =IF(OR(F5="",G5="",G5=0),"",IF(H5>0,"reduce light",ROUND(F5*210/G5/21.3,0)*21.3)) | O5: =IF(OR(M5="",N5="",U5=""),"",IF(AND(M5=1,N5>=0.9,N5<=1.1,U5>=0.70),"pass","FAIL")) | R5: =IF(OR(P5="",Q5=""),"",SQRT(0.5*(P5^2+Q5^2))) | S5: =IF(OR(P5="",Q5="",P5=0),"",Q5/P5)
A6: Everlight | B6: bare (ref) | C6: 1 | D6: 4 | E6: 38.2 | J6: =IF(OR(F6="",G6="",G6=0),"",IF(H6>0,"reduce light",ROUND(F6*210/G6/21.3,0)*21.3)) | O6: =IF(OR(M6="",N6="",U6=""),"",IF(AND(M6=1,N6>=0.9,N6<=1.1,U6>=0.70),"pass","FAIL")) | R6: =IF(OR(P6="",Q6=""),"",SQRT(0.5*(P6^2+Q6^2))) | S6: =IF(OR(P6="",Q6="",P6=0),"",Q6/P6)
A7: XL | B7: bare (ref) | C7: 1 | D7: 4 | E7: 21.7 | J7: =IF(OR(F7="",G7="",G7=0),"",IF(H7>0,"reduce light",ROUND(F7*210/G7/21.3,0)*21.3)) | O7: =IF(OR(M7="",N7="",U7=""),"",IF(AND(M7=1,N7>=0.9,N7<=1.1,U7>=0.70),"pass","FAIL")) | R7: =IF(OR(P7="",Q7=""),"",SQRT(0.5*(P7^2+Q7^2))) | S7: =IF(OR(P7="",Q7="",P7=0),"",Q7/P7)
A8: Kingbright | B8: bare (ref) | C8: 1 | D8: 4 | E8: 38.2 | J8: =IF(OR(F8="",G8="",G8=0),"",IF(H8>0,"reduce light",ROUND(F8*210/G8/21.3,0)*21.3)) | O8: =IF(OR(M8="",N8="",U8=""),"",IF(AND(M8=1,N8>=0.9,N8<=1.1,U8>=0.70),"pass","FAIL")) | R8: =IF(OR(P8="",Q8=""),"",SQRT(0.5*(P8^2+Q8^2))) | S8: =IF(OR(P8="",Q8="",P8=0),"",Q8/P8)
A9: Vishay | B9: 20 mm | C9: 1 | D9: 4 | E9: 78.8 | F9: 215 | G9: 213.6 | H9: 0 | I9: 0 | J9: =IF(OR(F9="",G9="",G9=0),"",IF(H9>0,"reduce light",ROUND(F9*210/G9/21.3,0)*21.3)) | K9: 437 | L9: 658 | M9: 1 | N9: 1.04 | O9: =IF(OR(M9="",N9="",U9=""),"",IF(AND(M9=1,N9>=0.9,N9<=1.1,U9>=0.70),"pass","FAIL")) | P9: 0.0347 | Q9: 0.0405 | R9: =IF(OR(P9="",Q9=""),"",SQRT(0.5*(P9^2+Q9^2))) | S9: =IF(OR(P9="",Q9="",P9=0),"",Q9/P9) | T9: cap 1. Worst blend of the study: fill 0.53 AND lobe 0.120 - the only build where the four LEDs are still azimuthally distinct (everything else 0.057-0.082). Also the shortest exposure (215 us = 0.3 px smear) and the worst sigma (0.0377). flux 434, blend FAIL | U9: 0.53 | V9: 0.12
A10: Everlight | B10: 20 mm | C10: 1 | D10: 4 | E10: 38.2 | F10: 2282 | G10: 208.7 | H10: 0 | I10: 0 | J10: =IF(OR(F10="",G10="",G10=0),"",IF(H10>0,"reduce light",ROUND(F10*210/G10/21.3,0)*21.3)) | K10: 774 | L10: 866 | M10: 1 | N10: 1.03 | O10: =IF(OR(M10="",N10="",U10=""),"",IF(AND(M10=1,N10>=0.9,N10<=1.1,U10>=0.70),"pass","FAIL")) | P10: 0.0188 | Q10: 0.0211 | R10: =IF(OR(P10="",Q10=""),"",SQRT(0.5*(P10^2+Q10^2))) | S10: =IF(OR(P10="",Q10="",P10=0),"",Q10/P10) | T10: cap 1. Lobe 0.057 is the lowest of the study - confirms all four LEDs survived the reversed connection. Intermediate on every axis, as beam angle predicts. flux 71, blend FAIL | U10: 0.77 | V10: 0.057
A11: XL | B11: 20 mm | C11: 1 | D11: 4 | E11: 21.7 | F11: 5967 | G11: 205.1 | H11: 0 | I11: 0 | J11: =IF(OR(F11="",G11="",G11=0),"",IF(H11>0,"reduce light",ROUND(F11*210/G11/21.3,0)*21.3)) | K11: 816 | L11: 921 | M11: 1 | N11: 1.01 | O11: =IF(OR(M11="",N11="",U11=""),"",IF(AND(M11=1,N11>=0.9,N11<=1.1,U11>=0.70),"pass","FAIL")) | P11: 0.0177 | Q11: 0.032 | R11: =IF(OR(P11="",Q11=""),"",SQRT(0.5*(P11^2+Q11^2))) | S11: =IF(OR(P11="",Q11="",P11=0),"",Q11/P11) | T11: cap 1. Fills FAR better than Kingbright (0.82 vs 0.59-0.67) and the rim is nearly circular (lobe 0.065). Confirms beam angle dominates over shell geometry. Cost: 5967 us. flux 28, blend FAIL | U11: 0.82 | V11: 0.065
A12: Kingbright | B12: 20 mm | C12: 1 | D12: 4 | E12: 38.2 | F12: 539 | G12: 212.7 | H12: 0 | I12: 0 | J12: =IF(OR(F12="",G12="",G12=0),"",IF(H12>0,"reduce light",ROUND(F12*210/G12/21.3,0)*21.3)) | K12: 603 | L12: 729 | M12: 1 | N12: 1.03 | O12: =IF(OR(M12="",N12="",U12=""),"",IF(AND(M12=1,N12>=0.9,N12<=1.1,U12>=0.70),"pass","FAIL")) | P12: 0.0233 | Q12: 0.0263 | R12: =IF(OR(P12="",Q12=""),"",SQRT(0.5*(P12^2+Q12^2))) | S12: =IF(OR(P12="",Q12="",P12=0),"",Q12/P12) | T12: cap 1, re-seat #2 (first fit: 557us area638 fill0.59 sigma0.0270). Repeats to 5% area, 0.01 fill, 8% sigma - the new no-support post-cured caps are twice as repeatable as the old ones (was 16% on sigma). Lobe 0.082 vs XL 0.059: azimuthally blended, so this is an ANNULUS not four lobes. flux 238, blend FAIL | U12: 0.6 | V12: 0.082
A13: Vishay | B13: 25 mm | C13: 1 | D13: 4 | E13: 78.8 | F13: 503 | G13: 211 | H13: 0 | I13: 0 | J13: =IF(OR(F13="",G13="",G13=0),"",IF(H13>0,"reduce light",ROUND(F13*210/G13/21.3,0)*21.3)) | K13: 718 | L13: 811 | M13: 1 | N13: 1.02 | O13: =IF(OR(M13="",N13="",U13=""),"",IF(AND(M13=1,N13>=0.9,N13<=1.1,U13>=0.70),"pass","FAIL")) | P13: 0.0206 | Q13: 0.0246 | R13: =IF(OR(P13="",Q13=""),"",SQRT(0.5*(P13^2+Q13^2))) | S13: =IF(OR(P13="",Q13="",P13=0),"",Q13/P13) | T13: cap 1. Biggest single improvement in the study: diameter gives +0.18 fill (0.53->0.71), lobe 0.120->0.067, sigma 40% better. Sigma now EQUALS Everlight 25/0.2 (0.0227 vs 0.0228) at 7x less smear (0.65 vs 4.5 px) - fails the fill gate but may win on the tracking criterion. flux 301, blend FAIL | U13: 0.71 | V13: 0.067
A14: Everlight | B14: 25 mm | C14: 1 | D14: 4 | E14: 38.2 | F14: 3469 | G14: 211.6 | H14: 0 | I14: 0 | J14: =IF(OR(F14="",G14="",G14=0),"",IF(H14>0,"reduce light",ROUND(F14*210/G14/21.3,0)*21.3)) | K14: 883 | L14: 997 | M14: 1 | N14: 1.03 | O14: =IF(OR(M14="",N14="",U14=""),"",IF(AND(M14=1,N14>=0.9,N14<=1.1,U14>=0.70),"pass","FAIL")) | P14: 0.0158 | Q14: 0.0281 | R14: =IF(OR(P14="",Q14=""),"",SQRT(0.5*(P14^2+Q14^2))) | S14: =IF(OR(P14="",Q14="",P14=0),"",Q14/P14) | T14: cap 1. PASSES THE BLEND GATE at 0.92, and at 3469 us that is 2.4x less smear than XL 25/0.2 needs for fill 1.00. Diameter is again the strong lever: fill 0.77 -> 0.92 for only 1.52x exposure. flux 54, blend pass | U14: 0.92 | V14: 0.064
A15: XL | B15: 25 mm | C15: 1 | D15: 4 | E15: 21.7 | F15: 8196 | G15: 215 | H15: 0 | I15: 0 | J15: =IF(OR(F15="",G15="",G15=0),"",IF(H15>0,"reduce light",ROUND(F15*210/G15/21.3,0)*21.3)) | K15: 954 | L15: 1069 | M15: 1 | N15: 1.02 | O15: =IF(OR(M15="",N15="",U15=""),"",IF(AND(M15=1,N15>=0.9,N15<=1.1,U15>=0.70),"pass","FAIL")) | P15: 0.016 | Q15: 0.021 | R15: =IF(OR(P15="",Q15=""),"",SQRT(0.5*(P15^2+Q15^2))) | S15: =IF(OR(P15="",Q15="",P15=0),"",Q15/P15) | T15: cap 1. BEST BUILD OF THE STUDY on optics: fill 1.00 (centre as bright as rim), lobe 0.059, largest area 954, lowest sigma 0.0186. For XL diameter is the strong lever (fill 0.82->1.00) and thickness the weak one (0.82->0.85). flux 25, blend pass | U15: 1 | V15: 0.059
A16: Kingbright | B16: 25 mm | C16: 1 | D16: 4 | E16: 38.2 | F16: 1114 | G16: 213.5 | H16: 0 | I16: 0 | J16: =IF(OR(F16="",G16="",G16=0),"",IF(H16>0,"reduce light",ROUND(F16*210/G16/21.3,0)*21.3)) | K16: 692 | L16: 778 | M16: 1 | N16: 1.03 | O16: =IF(OR(M16="",N16="",U16=""),"",IF(AND(M16=1,N16>=0.9,N16<=1.1,U16>=0.70),"pass","FAIL")) | P16: 0.0186 | Q16: 0.027 | R16: =IF(OR(P16="",Q16=""),"",SQRT(0.5*(P16^2+Q16^2))) | S16: =IF(OR(P16="",Q16="",P16=0),"",Q16/P16) | T16: cap 1, re-seat #2 (first: 1132us area702 fill0.66 sigma0.0221). Repeats to 1% area, 0.00 fill, 5% sigma. flux 133, blend FAIL | U16: 0.66 | V16: 0.071

Sheet A_Bench_run1
A1: RUN 1 - preliminary, superseded
A2: Frozen record of the first characterisation. Distance was never recorded and 8 of the 12 rows were saturated, so the sigmas here are not usable - a clipped blob also bands on alternate rows (measured 2026-08-30), which is what drove sigma_v to 3.2-3.5 px on Kingbright.
A3: LED Type | B3: Build | C3: Sample | D3: Drive I (mA) | E3: Exposure (us) | F3: Peak (0-255) | G3: Sat px | H3: Frames sat (of 200) | I3: Next exposure (us, aim 210) | J3: Sensor area (px) | K3: npix (refined) | L3: blobs (must be 1) | M3: w/h (want ~1.00) | N3: Blend gate | O3: sigma_u (px) | P3: sigma_v (px) | Q3: sigma_RMS (px) | R3: sig_v/sig_u (>3 = suspect) | S3: Notes
A4: EXAMPLE | B4: 20 mm | C4: 1 | D4: 38.2 | E4: 386 | F4: 218 | G4: 0 | H4: 0 | I4: =IF(OR(E4="",F4="",F4=0),"",IF(G4>0,"reduce light",ROUND(E4*210/F4/21.3,0)*21.3)) | J4: 984 | K4: 962 | L4: 1 | M4: 1.03 | N4: =IF(OR(L4="",M4=""),"",IF(AND(L4=1,M4>=0.9,M4<=1.1),"pass","FAIL")) | O4: 0.0298 | P4: 0.0271 | Q4: =IF(OR(O4="",P4=""),"",SQRT(0.5*(O4^2+P4^2))) | R4: =IF(OR(O4="",P4="",O4=0),"",P4/O4) | S4: peak in band, blend passes
A5: Vishay | B5: bare (ref) | C5: 1 | D5: 78.8 | E5: 85 | F5: 255 | G5: 71.3 | H5: 200 | I5: =IF(OR(E5="",F5="",F5=0),"",IF(G5>0,"reduce light",ROUND(E5*210/F5/21.3,0)*21.3)) | J5: 736 | K5: 812 | L5: 1 | M5: 1 | N5: =IF(OR(L5="",M5=""),"",IF(AND(L5=1,M5>=0.9,M5<=1.1),"pass","FAIL")) | O5: 0.0269 | P5: 0.0216 | Q5: =IF(OR(O5="",P5=""),"",SQRT(0.5*(O5^2+P5^2))) | R5: =IF(OR(O5="",P5="",O5=0),"",P5/O5) | S5: Exposure_uS = 85, Couldn't get it to be unsaturated : saturated 200/200 frames
A6: Everlight | B6: bare (ref) | C6: 1 | D6: 38.2 | E6: 85 | F6: 255 | G6: 42.1 | I6: =IF(OR(E6="",F6="",F6=0),"",IF(G6>0,"reduce light",ROUND(E6*210/F6/21.3,0)*21.3)) | J6: 163 | K6: 237 | L6: 1 | M6: 0.9 | N6: =IF(OR(L6="",M6=""),"",IF(AND(L6=1,M6>=0.9,M6<=1.1),"pass","FAIL")) | O6: 0.0409 | P6: 0.6624 | Q6: =IF(OR(O6="",P6=""),"",SQRT(0.5*(O6^2+P6^2))) | R6: =IF(OR(O6="",P6="",O6=0),"",P6/O6) | S6: Exposure_uS = 85
A7: XL | B7: bare (ref) | C7: 1 | D7: 21.7 | E7: 235 | F7: 255 | G7: 7 | I7: =IF(OR(E7="",F7="",F7=0),"",IF(G7>0,"reduce light",ROUND(E7*210/F7/21.3,0)*21.3)) | J7: 280 | K7: 386 | L7: 1 | N7: =IF(OR(L7="",M7=""),"",IF(AND(L7=1,M7>=0.9,M7<=1.1),"pass","FAIL")) | O7: 0.0647 | P7: 0.2962 | Q7: =IF(OR(O7="",P7=""),"",SQRT(0.5*(O7^2+P7^2))) | R7: =IF(OR(O7="",P7="",O7=0),"",P7/O7) | S7: CHECK - row was entered shifted; unexplained value 3.5 sat in Sensor area. Exposure_uS = 235
A8: Kingbright | B8: bare (ref) | C8: 1 | D8: 38.2 | E8: 42 | F8: 255 | G8: 89.7 | I8: =IF(OR(E8="",F8="",F8=0),"",IF(G8>0,"reduce light",ROUND(E8*210/F8/21.3,0)*21.3)) | J8: 323 | K8: 395 | L8: 1 | M8: 1.13 | N8: =IF(OR(L8="",M8=""),"",IF(AND(L8=1,M8>=0.9,M8<=1.1),"pass","FAIL")) | O8: 0.0972 | P8: 0.2132 | Q8: =IF(OR(O8="",P8=""),"",SQRT(0.5*(O8^2+P8^2))) | R8: =IF(OR(O8="",P8="",O8=0),"",P8/O8) | S8: Exposure_uS = 42
A9: Vishay | B9: 20 mm | C9: 1 | D9: 78.8 | E9: 85 | F9: 255 | G9: 58 | H9: 200 | I9: =IF(OR(E9="",F9="",F9=0),"",IF(G9>0,"reduce light",ROUND(E9*210/F9/21.3,0)*21.3)) | J9: 248 | K9: 328 | L9: 1 | M9: 1 | N9: =IF(OR(L9="",M9=""),"",IF(AND(L9=1,M9>=0.9,M9<=1.1),"pass","FAIL")) | O9: 0.0427 | P9: 0.0166 | Q9: =IF(OR(O9="",P9=""),"",SQRT(0.5*(O9^2+P9^2))) | R9: =IF(OR(O9="",P9="",O9=0),"",P9/O9) | S9: Exposure_uS = 85, Couldn't get it to be unsaturated: saturated 200/200 frames
A10: Everlight | B10: 20 mm | C10: 1 | D10: 38.2 | E10: 386 | F10: 194 | G10: 0 | I10: =IF(OR(E10="",F10="",F10=0),"",IF(G10>0,"reduce light",ROUND(E10*210/F10/21.3,0)*21.3)) | J10: 541 | K10: 716 | L10: 1 | M10: 1 | N10: =IF(OR(L10="",M10=""),"",IF(AND(L10=1,M10>=0.9,M10<=1.1),"pass","FAIL")) | O10: 0.0263 | P10: 0.04 | Q10: =IF(OR(O10="",P10=""),"",SQRT(0.5*(O10^2+P10^2))) | R10: =IF(OR(O10="",P10="",O10=0),"",P10/O10) | S10: Exposure_uS = 386
A11: XL | B11: 20 mm | C11: 1 | D11: 21.7 | E11: 493 | F11: 187 | G11: 0 | I11: =IF(OR(E11="",F11="",F11=0),"",IF(G11>0,"reduce light",ROUND(E11*210/F11/21.3,0)*21.3)) | J11: 855 | K11: 1117 | N11: =IF(OR(L11="",M11=""),"",IF(AND(L11=1,M11>=0.9,M11<=1.1),"pass","FAIL")) | O11: 0.0305 | P11: 0.0305 | Q11: =IF(OR(O11="",P11=""),"",SQRT(0.5*(O11^2+P11^2))) | R11: =IF(OR(O11="",P11="",O11=0),"",P11/O11) | S11: Exposure_uS = 493
A12: Kingbright | B12: 20 mm | C12: 1 | D12: 38.2 | E12: 128 | F12: 252 | G12: 8.1 | H12: 188 | I12: =IF(OR(E12="",F12="",F12=0),"",IF(G12>0,"reduce light",ROUND(E12*210/F12/21.3,0)*21.3)) | J12: 177 | K12: 298 | L12: 1 | M12: 1 | N12: =IF(OR(L12="",M12=""),"",IF(AND(L12=1,M12>=0.9,M12<=1.1),"pass","FAIL")) | O12: 0.1574 | P12: 3.2473 | Q12: =IF(OR(O12="",P12=""),"",SQRT(0.5*(O12^2+P12^2))) | R12: =IF(OR(O12="",P12="",O12=0),"",P12/O12) | S12: Exposure_uS = 128, Couldn't get it to be unsaturated: saturated 188/200 frames
A13: Vishay | B13: 25 mm | C13: 1 | D13: 78.8 | E13: 85 | F13: 255 | G13: 67.7 | H13: 200 | I13: =IF(OR(E13="",F13="",F13=0),"",IF(G13>0,"reduce light",ROUND(E13*210/F13/21.3,0)*21.3)) | J13: 347 | K13: 447 | L13: 1 | M13: 1.13 | N13: =IF(OR(L13="",M13=""),"",IF(AND(L13=1,M13>=0.9,M13<=1.1),"pass","FAIL")) | O13: 0.0536 | P13: 0.0165 | Q13: =IF(OR(O13="",P13=""),"",SQRT(0.5*(O13^2+P13^2))) | R13: =IF(OR(O13="",P13="",O13=0),"",P13/O13) | S13: Exposure_uS = 85, Couldn't get it to be unsaturated: saturated 200/200 frames
A14: Everlight | B14: 25 mm | C14: 1 | D14: 38.2 | E14: 493 | F14: 194 | G14: 0 | I14: =IF(OR(E14="",F14="",F14=0),"",IF(G14>0,"reduce light",ROUND(E14*210/F14/21.3,0)*21.3)) | J14: 739 | K14: 1018 | L14: 1 | M14: 1 | N14: =IF(OR(L14="",M14=""),"",IF(AND(L14=1,M14>=0.9,M14<=1.1),"pass","FAIL")) | O14: 0.0237 | P14: 0.0319 | Q14: =IF(OR(O14="",P14=""),"",SQRT(0.5*(O14^2+P14^2))) | R14: =IF(OR(O14="",P14="",O14=0),"",P14/O14) | S14: Exposure_uS = 493
A15: XL | B15: 25 mm | C15: 1 | D15: 21.7 | E15: 686 | F15: 143 | G15: 0 | I15: =IF(OR(E15="",F15="",F15=0),"",IF(G15>0,"reduce light",ROUND(E15*210/F15/21.3,0)*21.3)) | J15: 444 | K15: 639 | L15: 1 | M15: 1 | N15: =IF(OR(L15="",M15=""),"",IF(AND(L15=1,M15>=0.9,M15<=1.1),"pass","FAIL")) | O15: 0.0294 | P15: 0.0287 | Q15: =IF(OR(O15="",P15=""),"",SQRT(0.5*(O15^2+P15^2))) | R15: =IF(OR(O15="",P15="",O15=0),"",P15/O15) | S15: Exposure_uS = 686
A16: Kingbright | B16: 25 mm | C16: 1 | D16: 38.2 | E16: 128 | F16: 248 | G16: 5.3 | H16: 124 | I16: =IF(OR(E16="",F16="",F16=0),"",IF(G16>0,"reduce light",ROUND(E16*210/F16/21.3,0)*21.3)) | J16: 163 | K16: 282 | L16: 1 | M16: 1 | N16: =IF(OR(L16="",M16=""),"",IF(AND(L16=1,M16>=0.9,M16<=1.1),"pass","FAIL")) | O16: 0.0712 | P16: 3.5417 | Q16: =IF(OR(O16="",P16=""),"",SQRT(0.5*(O16^2+P16^2))) | R16: =IF(OR(O16="",P16="",O16=0),"",P16/O16) | S16: Exposure_uS = 128, Couldn't get it to be unsaturated: saturated 124/200 frames

Sheet A_Bench_run2
A1: RUN 2 - 4 m, 0.2 mm wall, 2026-08-30
A2: Complete 12-row set and the source of every conclusion in NOTES.md. Superseded only because the rig was packed up afterwards, so distance and focus will differ on rebuild - exposure and area are not comparable across a teardown. Sigma and fill should be.
A3: LED Type | B3: Build | C3: Sample | D3: Distance (m) | E3: Drive I (mA) | F3: Exposure (us) | G3: Peak (0-255) | H3: Sat px | I3: Frames sat (of 200) | J3: Next exposure (us, aim 210) | K3: Sensor area (px) | L3: npix (refined) | M3: blobs (must be 1) | N3: w/h (want ~1.00) | O3: Blend gate | P3: sigma_u (px) | Q3: sigma_v (px) | R3: sigma_RMS (px) | S3: sig_v/sig_u (>3 = suspect) | T3: Notes | U3: Fill (centre/rim)
A4: EXAMPLE | B4: 20 mm | C4: 1 | E4: 38.2 | F4: 386 | G4: 218 | H4: 0 | I4: 0 | J4: =IF(OR(F4="",G4="",G4=0),"",IF(H4>0,"reduce light",ROUND(F4*210/G4/21.3,0)*21.3)) | K4: 984 | L4: 962 | M4: 1 | N4: 1.03 | O4: =IF(OR(M4="",N4="",U4=""),"",IF(AND(M4=1,N4>=0.9,N4<=1.1,U4>=0.85),"pass","FAIL")) | P4: 0.0298 | Q4: 0.0271 | R4: =IF(OR(P4="",Q4=""),"",SQRT(0.5*(P4^2+Q4^2))) | S4: =IF(OR(P4="",Q4="",P4=0),"",Q4/P4) | T4: peak in band, blend passes
A5: Vishay | B5: bare (ref) | C5: 1 | D5: 4 | E5: 78.8 | F5: 53 | G5: 255 | H5: 18.7 | I5: 200 | J5: =IF(OR(F5="",G5="",G5=0),"",IF(H5>0,"reduce light",ROUND(F5*210/G5/21.3,0)*21.3)) | K5: 56 | L5: 97 | M5: 8 | N5: 8.2 | O5: =IF(OR(M5="",N5="",U5=""),"",IF(AND(M5=1,N5>=0.9,N5<=1.1,U5>=0.85),"pass","FAIL")) | R5: =IF(OR(P5="",Q5=""),"",SQRT(0.5*(P5^2+Q5^2))) | S5: =IF(OR(P5="",Q5="",P5=0),"",Q5/P5) | T5: VOID - no in-band exposure exists at 4 m. 17 us -> peak below THRESH_LO, 53 us -> clipped in 200/200 frames. Clipping bands alternate rows, which split the disc into 8 blobs; the largest is a 56 px sliver. sigma on that sliver read 0.0678/0.0240 - plausible-looking and meaningless, so it is NOT entered. Needs ~4x attenuation: 120 ohm in place of 33 ohm.
A6: Everlight | B6: bare (ref) | C6: 1 | D6: 4 | E6: 38.2 | F6: 521 | G6: 204.7 | H6: 0 | I6: 0 | J6: =IF(OR(F6="",G6="",G6=0),"",IF(H6>0,"reduce light",ROUND(F6*210/G6/21.3,0)*21.3)) | K6: 406 | L6: 608 | M6: 1 | N6: 1.02 | O6: =IF(OR(M6="",N6="",U6=""),"",IF(AND(M6=1,N6>=0.9,N6<=1.1,U6>=0.85),"pass","FAIL")) | P6: 0.0341 | Q6: 0.0354 | R6: =IF(OR(P6="",Q6=""),"",SQRT(0.5*(P6^2+Q6^2))) | S6: =IF(OR(P6="",Q6="",P6=0),"",Q6/P6) | T6: peak 204.7 (max 220), sat 0, blend pass, sig_v/sig_u 1.04
A7: XL | B7: bare (ref) | C7: 1 | D7: 4 | E7: 21.7 | F7: 1707 | G7: 207.4 | H7: 0 | I7: 0 | J7: =IF(OR(F7="",G7="",G7=0),"",IF(H7>0,"reduce light",ROUND(F7*210/G7/21.3,0)*21.3)) | K7: 506 | L7: 656 | M7: 3 | N7: 1 | O7: =IF(OR(M7="",N7="",U7=""),"",IF(AND(M7=1,N7>=0.9,N7<=1.1,U7>=0.85),"pass","FAIL")) | P7: 0.0249 | Q7: 0.0285 | R7: =IF(OR(P7="",Q7=""),"",SQRT(0.5*(P7^2+Q7^2))) | S7: =IF(OR(P7="",Q7="",P7=0),"",Q7/P7) | T7: Bare: blobs 3 / fill 0.61 is the RAW cluster resolving into separate LEDs, which is expected with no diffuser - not a build fault. The blend gate only means something on a diffused row. peak 207.4 (max 226), sat 0, blend FAIL, sig_v/sig_u 1.14 | U7: 0.61
A8: Kingbright | B8: bare (ref) | C8: 1 | D8: 4 | E8: 38.2 | F8: 53 | G8: 255 | H8: 16.8 | I8: 200 | J8: =IF(OR(F8="",G8="",G8=0),"",IF(H8>0,"reduce light",ROUND(F8*210/G8/21.3,0)*21.3)) | K8: 47 | L8: 85 | M8: 8 | N8: 7.98 | O8: =IF(OR(M8="",N8="",U8=""),"",IF(AND(M8=1,N8>=0.9,N8<=1.1,U8>=0.85),"pass","FAIL")) | R8: =IF(OR(P8="",Q8=""),"",SQRT(0.5*(P8^2+Q8^2))) | S8: =IF(OR(P8="",Q8="",P8=0),"",Q8/P8) | T8: VOID - same failure as Vishay bare: 17 us leaves the blob below THRESH_LO, 35 us clips. Clipped in 200/200 frames, split into 8 banded slivers (w/h 7.98). Sigma NOT entered. Very bright part: needs Vishay-like exposure at HALF the current. peak 255.0 (max 255), sat 16.8, blend FAIL, sig_v/sig_u 0.19 | U8: 1.8
A9: Vishay | B9: 20 mm | C9: 1 | D9: 4 | E9: 78.8 | F9: 323 | G9: 201.4 | H9: 0 | I9: 0 | J9: =IF(OR(F9="",G9="",G9=0),"",IF(H9>0,"reduce light",ROUND(F9*210/G9/21.3,0)*21.3)) | K9: 569 | L9: 680 | M9: 1 | N9: 1 | O9: =IF(OR(M9="",N9="",U9=""),"",IF(AND(M9=1,N9>=0.9,N9<=1.1,U9>=0.85),"pass","FAIL")) | P9: 0.0263 | Q9: 0.029 | R9: =IF(OR(P9="",Q9=""),"",SQRT(0.5*(P9^2+Q9^2))) | S9: =IF(OR(P9="",Q9="",P9=0),"",Q9/P9) | T9: NOT BLENDING - images as a RING: centre only 67% of rim brightness. One connected round blob, so blobs and w/h both pass; only fill catches it. peak 201.4 (max 218), sat 0, blend FAIL, sig_v/sig_u 1.10 | U9: 0.67
A10: Everlight | B10: 20 mm | C10: 1 | D10: 4 | E10: 38.2 | F10: 2588 | G10: 208.5 | H10: 0 | I10: 0 | J10: =IF(OR(F10="",G10="",G10=0),"",IF(H10>0,"reduce light",ROUND(F10*210/G10/21.3,0)*21.3)) | K10: 752 | L10: 857 | M10: 1 | N10: 0.98 | O10: =IF(OR(M10="",N10="",U10=""),"",IF(AND(M10=1,N10>=0.9,N10<=1.1,U10>=0.85),"pass","FAIL")) | P10: 0.0173 | Q10: 0.016 | R10: =IF(OR(P10="",Q10=""),"",SQRT(0.5*(P10^2+Q10^2))) | S10: =IF(OR(P10="",Q10="",P10=0),"",Q10/P10) | T10: PROVISIONAL - diffuser was cracked; reprint and re-measure. Blob stayed round (w/h 0.98, 1 blob) so the crack did not leak a hot spot. peak 208.5 (max 229), sat 0, blend pass, sig_v/sig_u 0.92
A11: XL | B11: 20 mm | C11: 1 | D11: 4 | E11: 21.7 | F11: 5985 | G11: 218 | H11: 0 | I11: 0 | J11: =IF(OR(F11="",G11="",G11=0),"",IF(H11>0,"reduce light",ROUND(F11*210/G11/21.3,0)*21.3)) | K11: 823 | L11: 923 | M11: 1 | N11: 1 | O11: =IF(OR(M11="",N11="",U11=""),"",IF(AND(M11=1,N11>=0.9,N11<=1.1,U11>=0.85),"pass","FAIL")) | P11: 0.015 | Q11: 0.022 | R11: =IF(OR(P11="",Q11=""),"",SQRT(0.5*(P11^2+Q11^2))) | S11: =IF(OR(P11="",Q11="",P11=0),"",Q11/P11) | T11: Best blend measured: fill 0.99, essentially uniform. Targeted first try. Cost is 5985 us = ~18 px smear at 3000 px/s. peak 218.0 (max 231), sat 0, blend pass, sig_v/sig_u 1.47 | U11: 0.99
A12: Kingbright | B12: 20 mm | C12: 1 | D12: 4 | E12: 38.2 | F12: 1096 | G12: 199.1 | H12: 0 | I12: 0 | J12: =IF(OR(F12="",G12="",G12=0),"",IF(H12>0,"reduce light",ROUND(F12*210/G12/21.3,0)*21.3)) | K12: 683 | L12: 773 | M12: 1 | N12: 0.99 | O12: =IF(OR(M12="",N12="",U12=""),"",IF(AND(M12=1,N12>=0.9,N12<=1.1,U12>=0.85),"pass","FAIL")) | P12: 0.024 | Q12: 0.022 | R12: =IF(OR(P12="",Q12=""),"",SQRT(0.5*(P12^2+Q12^2))) | S12: =IF(OR(P12="",Q12="",P12=0),"",Q12/P12) | T12: Rings (fill 0.77) but less than Vishay. Measured 3x independently at 898/970/1096 us: sigma_RMS 0.0245 / 0.0234 / 0.0230, fill 0.73/0.74/0.77 - so run-to-run repeatability is ~3%, and differences under ~5% between builds are not significant. peak 199.1 (max 215), sat 0, blend FAIL, sig_v/sig_u 0.92 | U12: 0.77
A13: Vishay | B13: 25 mm | C13: 1 | D13: 4 | E13: 78.8 | F13: 251 | G13: 209.5 | H13: 0 | I13: 0 | J13: =IF(OR(F13="",G13="",G13=0),"",IF(H13>0,"reduce light",ROUND(F13*210/G13/21.3,0)*21.3)) | K13: 516 | L13: 662 | M13: 1 | N13: 1 | O13: =IF(OR(M13="",N13="",U13=""),"",IF(AND(M13=1,N13>=0.9,N13<=1.1,U13>=0.85),"pass","FAIL")) | P13: 0.0306 | Q13: 0.0358 | R13: =IF(OR(P13="",Q13=""),"",SQRT(0.5*(P13^2+Q13^2))) | S13: =IF(OR(P13="",Q13="",P13=0),"",Q13/P13) | T13: NOT BLENDING - still a ring (fill 0.69). The larger shell did NOT fix it, so the ring is the LED beam pattern, not the diameter. Needs less exposure and gives LESS area than the 20 mm, which is backwards - check the two caps are the same material, wall thickness and infill. peak 209.5 (max 223), sat 0, blend FAIL, sig_v/sig_u 1.17 | U13: 0.69
A14: Everlight | B14: 25 mm | C14: 1 | D14: 4 | E14: 38.2 | F14: 2983 | G14: 217.4 | H14: 0 | I14: 0 | J14: =IF(OR(F14="",G14="",G14=0),"",IF(H14>0,"reduce light",ROUND(F14*210/G14/21.3,0)*21.3)) | K14: 845 | L14: 960 | M14: 1 | N14: 0.97 | O14: =IF(OR(M14="",N14="",U14=""),"",IF(AND(M14=1,N14>=0.9,N14<=1.1,U14>=0.85),"pass","FAIL")) | P14: 0.0176 | Q14: 0.0171 | R14: =IF(OR(P14="",Q14=""),"",SQRT(0.5*(P14^2+Q14^2))) | S14: =IF(OR(P14="",Q14="",P14=0),"",Q14/P14) | T14: Targeted first try. peak 217.4 (max 233), sat 0, blend pass, sig_v/sig_u 0.97
A15: XL | B15: 25 mm | C15: 1 | D15: 4 | E15: 21.7 | F15: 6057 | G15: 205.6 | H15: 0 | I15: 0 | J15: =IF(OR(F15="",G15="",G15=0),"",IF(H15>0,"reduce light",ROUND(F15*210/G15/21.3,0)*21.3)) | K15: 874 | L15: 1002 | M15: 1 | N15: 1 | O15: =IF(OR(M15="",N15="",U15=""),"",IF(AND(M15=1,N15>=0.9,N15<=1.1,U15>=0.85),"pass","FAIL")) | P15: 0.0165 | Q15: 0.0157 | R15: =IF(OR(P15="",Q15=""),"",SQRT(0.5*(P15^2+Q15^2))) | S15: =IF(OR(P15="",Q15="",P15=0),"",Q15/P15) | T15: Best optics in the study: lowest sigma, largest area, fill 1.08 (centre slightly brighter than rim), isotropic. Cost is 6057 us = ~18 px smear at 3000 px/s. peak 205.6 (max 225), sat 0, blend pass, sig_v/sig_u 0.95 | U15: 1.08
A16: Kingbright | B16: 25 mm | C16: 1 | D16: 4 | E16: 38.2 | F16: 1186 | G16: 210.4 | H16: 0 | I16: 0 | J16: =IF(OR(F16="",G16="",G16=0),"",IF(H16>0,"reduce light",ROUND(F16*210/G16/21.3,0)*21.3)) | K16: 727 | L16: 818 | M16: 1 | N16: 1 | O16: =IF(OR(M16="",N16="",U16=""),"",IF(AND(M16=1,N16>=0.9,N16<=1.1,U16>=0.85),"pass","FAIL")) | P16: 0.015 | Q16: 0.0173 | R16: =IF(OR(P16="",Q16=""),"",SQRT(0.5*(P16^2+Q16^2))) | S16: =IF(OR(P16="",Q16="",P16=0),"",Q16/P16) | T16: Strongest overall candidate: sigma tied with XL 25 mm for best in the study but at 1186 us instead of 6057 - 5x less smear. Fill 0.82 just misses the 0.85 gate; diameter helped here (0.77 -> 0.82) unlike on Vishay. peak 210.4 (max 240), sat 0, blend FAIL, sig_v/sig_u 1.15 | U16: 0.82

Sheet B_Angle
A1: TEST B - Isotropy: head-on (0 deg) vs upright (90 deg)
A2: The LEDs sit on a flat PCB, so 0 deg looks down the emission axis and 90 deg views it from the side - the extreme of beam angle. A spherical diffuser should make the marker look the SAME from both. The 90/0 ratios are the test: near 1.00 = isotropic. Add 45 deg ONLY if 0 and 90 diverge. 25 mm builds only; marker is moved, camera is NOT - rotating the camera changes framing, background and focus distance all at once.
A4: LED Type | B4: Wall (mm) | C4: Angle (deg) | D4: Exposure (us) | E4: Peak | F4: Sensor area (px) | G4: npix | H4: blobs | I4: w/h | J4: Fill | K4: Lobe | L4: sigma_u (px) | M4: sigma_v (px) | N4: sigma_RMS (px) | O4: Exposure 90/0 | P4: Area 90/0 | Q4: Fill 90/0 | R4: Notes
A5: Vishay | B5: 0.2 | C5: 0 | D5: 485 | E5: 211.1 | F5: 703 | G5: 794 | H5: 1 | I5: 1 | J5: 0.7 | K5: 0.084 | L5: 0.0251 | M5: 0.0336 | N5: =IF(OR(L5="",M5=""),"",SQRT(0.5*(L5^2+M5^2))) | R5: cap 1, head-on baseline for the thin-wall Vishay.
A6: Vishay | B6: 0.2 | C6: 90 | D6: 6183 | E6: 204.5 | F6: 1018 | G6: 1129 | H6: 1 | I6: 0.97 | J6: 1.04 | K6: 0.063 | L6: 0.0193 | M6: 0.0167 | N6: =IF(OR(L6="",M6=""),"",SQRT(0.5*(L6^2+M6^2))) | O6: =IF(OR(D6="",D5=""),"",D6/D5) | P6: =IF(OR(F6="",F5=""),"",F6/F5) | Q6: =IF(OR(J6="",J5=""),"",J6/J5) | R6: 12.7x anisotropy - WORSE than the 0.4mm wall's 8.8x, as predicted. Thickness buys isotropy (31% less anisotropic) even though it barely moved fill or sigma at 25 mm. That is a new and better reason to prefer the thicker shell.
A7: Vishay | B7: 0.4 | C7: 0 | D7: 557 | E7: 203.5 | F7: 742 | G7: 838 | H7: 1 | I7: 1.03 | J7: 0.73 | K7: 0.076 | L7: 0.0248 | M7: 0.0219 | N7: =IF(OR(L7="",M7=""),"",SQRT(0.5*(L7^2+M7^2))) | R7: cap 1, head-on baseline. Consistent with the 4-cap mean (602us, area 751, fill 0.74, sigma 0.0240) - all inside the measured spread.
A8: Vishay | B8: 0.4 | C8: 90 | D8: 4925 | E8: 199.7 | F8: 978 | G8: 1097 | H8: 1 | I8: 0.96 | J8: 1.02 | K8: 0.065 | L8: 0.0198 | M8: 0.017 | N8: =IF(OR(L8="",M8=""),"",SQRT(0.5*(L8^2+M8^2))) | O8: =IF(OR(D8="",D7=""),"",D8/D7) | P8: =IF(OR(F8="",F7=""),"",F8/F7) | Q8: =IF(OR(J8="",J7=""),"",J8/J7) | R8: 8.8x MORE EXPOSURE than head-on. Optically better from the side (fill 0.73->1.02, area +32%, sigma 0.0234->0.0185) because you see the shell wall lit at grazing incidence rather than the LEDs' direct beams - but 8.8x exceeds the ~3x dynamic range between THRESH_LO and saturation, so no fixed exposure covers both views.
A9: Kingbright | B9: 0.2 | C9: 0 | D9: 952 | E9: 213.5 | F9: 676 | G9: 762 | H9: 1 | I9: 1.02 | J9: 0.65 | K9: 0.067 | L9: 0.0248 | M9: 0.0255 | N9: =IF(OR(L9="",M9=""),"",SQRT(0.5*(L9^2+M9^2))) | R9: cap 1, head-on baseline. THT part - stands proud of the board, unlike the flat SMD emitters.
A10: Kingbright | B10: 0.2 | C10: 90 | D10: 18801 | E10: 206.8 | F10: 893 | G10: 1008 | H10: 1 | I10: 0.97 | J10: 0.94 | K10: 0.062 | L10: 0.016 | M10: 0.0209 | N10: =IF(OR(L10="",M10=""),"",SQRT(0.5*(L10^2+M10^2))) | O10: =IF(OR(D10="",D9=""),"",D10/D9) | P10: =IF(OR(F10="",F9=""),"",F10/F9) | Q10: =IF(OR(J10="",J9=""),"",J10/J9) | R10: 19.7x - the WORST anisotropy of the study, worse even than Vishay. The THT domed lens concentrates light forward by design, so it illuminates the shell over the smallest solid angle of any part here. Standoff from being through-hole does not compensate.
A11: Kingbright | B11: 0.4 | C11: 0 | N11: =IF(OR(L11="",M11=""),"",SQRT(0.5*(L11^2+M11^2)))
A12: Kingbright | B12: 0.4 | C12: 90 | N12: =IF(OR(L12="",M12=""),"",SQRT(0.5*(L12^2+M12^2))) | O12: =IF(OR(D12="",D11=""),"",D12/D11) | P12: =IF(OR(F12="",F11=""),"",F12/F11) | Q12: =IF(OR(J12="",J11=""),"",J12/J11)
A13: Everlight | B13: 0.2 | C13: 0 | D13: 3469 | E13: 214 | F13: 888 | G13: 1004 | H13: 1 | I13: 0.99 | J13: 0.92 | K13: 0.056 | L13: 0.018 | M13: 0.0219 | N13: =IF(OR(L13="",M13=""),"",SQRT(0.5*(L13^2+M13^2))) | R13: cap 1, head-on baseline. Reproduces the run-4 row exactly (3469us, area 883, fill 0.92).
A14: Everlight | B14: 0.2 | C14: 90 | D14: 12780 | E14: 206.9 | F14: 987 | G14: 1093 | H14: 1 | I14: 1 | J14: 1.02 | K14: 0.056 | L14: 0.0194 | M14: 0.0147 | N14: =IF(OR(L14="",M14=""),"",SQRT(0.5*(L14^2+M14^2))) | O14: =IF(OR(D14="",D13=""),"",D14/D13) | P14: =IF(OR(F14="",F13=""),"",F14/F13) | Q14: =IF(OR(J14="",J13=""),"",J14/J13) | R14: 3.68x anisotropy - just OVER the 3.1x budget at THRESH_LO 80. Viable only if THRESH_LO drops to ~50, which trades against blob merging.
A15: Everlight | B15: 0.4 | C15: 0 | D15: 3756 | E15: 212.4 | F15: 910 | G15: 1020 | H15: 1 | I15: 1.01 | J15: 0.94 | K15: 0.058 | L15: 0.0157 | M15: 0.0198 | N15: =IF(OR(L15="",M15=""),"",SQRT(0.5*(L15^2+M15^2))) | R15: cap 1, head-on baseline. Reproduces the run-4 row exactly (3756us, area 910, fill 0.94).
A16: Everlight | B16: 0.4 | C16: 90 | D16: 12366 | E16: 205.2 | F16: 991 | G16: 1105 | H16: 1 | I16: 1.02 | J16: 1.03 | K16: 0.054 | L16: 0.0202 | M16: 0.0266 | N16: =IF(OR(L16="",M16=""),"",SQRT(0.5*(L16^2+M16^2))) | O16: =IF(OR(D16="",D15=""),"",D16/D15) | P16: =IF(OR(F16="",F15=""),"",F16/F15) | Q16: =IF(OR(J16="",J15=""),"",J16/J15) | R16: 3.29x - thickness improved it 11% (3.68->3.29) but still over budget. Needs head-on peak 263 at THRESH_LO 80, above saturation. Viable only at TL<=70 and with almost no exposure margin, which the 20% cap-to-cap spread would eat.
A17: XL | B17: 0.2 | C17: 0 | D17: 8520 | E17: 210.5 | F17: 952 | G17: 1068 | H17: 1 | I17: 1 | J17: 1.03 | K17: 0.056 | L17: 0.0169 | M17: 0.0305 | N17: =IF(OR(L17="",M17=""),"",SQRT(0.5*(L17^2+M17^2))) | R17: cap 1, head-on baseline. Matches the run-4 row (8196us, area 954, fill 1.00) within cap spread.
A18: XL | B18: 0.2 | C18: 90 | D18: 16033 | E18: 206.8 | F18: 950 | G18: 1063 | H18: 1 | I18: 1.03 | J18: 0.99 | K18: 0.062 | L18: 0.0213 | M18: 0.0227 | N18: =IF(OR(L18="",M18=""),"",SQRT(0.5*(L18^2+M18^2))) | O18: =IF(OR(D18="",D17=""),"",D18/D17) | P18: =IF(OR(F18="",F17=""),"",F18/F17) | Q18: =IF(OR(J18="",J17=""),"",J18/J17) | R18: ONLY 1.88x anisotropy - inside the ~3.1x fixed-exposure budget, where Vishay needed 8.8-12.7x. Area 950 vs 952 and fill 0.99 vs 1.03: XL presents the SAME size and blend from both directions, just 1.88x dimmer. This is the only marker so far that can be tracked at a fixed exposure.
A19: XL | B19: 0.4 | C19: 0 | N19: =IF(OR(L19="",M19=""),"",SQRT(0.5*(L19^2+M19^2)))
A20: XL | B20: 0.4 | C20: 90 | N20: =IF(OR(L20="",M20=""),"",SQRT(0.5*(L20^2+M20^2))) | O20: =IF(OR(D20="",D19=""),"",D20/D19) | P20: =IF(OR(F20="",F19=""),"",F20/F19) | Q20: =IF(OR(J20="",J19=""),"",J20/J19)
A22: HOW TO READ THIS
A23: The 90/0 ratios are the whole test. Exposure 90/0 near 1.00 means the marker is as bright from the side as head-on; area 90/0 near 1.00 means it presents the same size; fill 90/0 near 1.00 means it blends as well. A sphere that works should give all three near unity REGARDLESS of the LED inside it.
A24: Expect the ordering to track beam angle if the diffuser is NOT doing its job: Vishay (narrowest) worst, XL (widest) best. If that ordering does NOT appear, the sphere has succeeded in making beam angle irrelevant - which is the result you want.
A25: At 90 deg the PCB and mount come into view and the open base of the shell may show. Watch lobe and w/h for asymmetry that is the MOUNT rather than the marker.
A26: Add 45 deg only if 0 and 90 diverge. If the two extremes agree, nothing interesting happens between them.
A27: Re-target the exposure at every angle - a dimmer 90 deg view needs more exposure, and rows are only comparable at matched peak (205-215).

Sheet C_Range
A1: TEST C - Range, at 0 deg and 90 deg
A2: 25 mm / 0.2 mm caps. Kingbright dropped - 19.7x anisotropy puts it out regardless of range. The 90 deg rows are the BINDING case: a marker detected at 90 deg is certainly detected at 0 deg, so the 90 deg far limit IS the operating range and it sets how many cameras the arena needs.
A3: RUN 3 - 10 Sep, CORRIDOR (not the arena). Camera 1, filter fitted, focus as locked 9 Sep - NOT re-touched. INSTRUMENT CHANGE: blob selection is now PEAK-based, not area-based. A corridor wall reflection is dimmer but more SPREAD OUT, so the old max-by-pixels pick locks onto the reflection at the long exposures this sweep uses (at 120 ms: reflection 463 px/peak 157 vs marker 325 px/peak 204). Run-2 rows were arena, single source, so they are unaffected. VENUE CAVEAT: reflections are in frame (blobs=3 at 8 m) and the marker is not isolated from its surround, so ABSOLUTE exposures do not transfer to the arena. Build-to-build RANKING is the intended use and is robust to a common-mode surround term. MARKER SIZE UNEXPLAINED: resolved as a ~68 px disc at 8 m vs ~7 px geometric for a 25 mm cap. Not defocus (blur circle <2.5 px for any plausible focus - would need focus at 52 mm), not saturation (clean at peak 211), not the sideways lobe (0 deg and 90 deg give rms_r 26.2 vs 24.8, i.e. unchanged). Most likely the LED plus an illuminated surround. OPEN.
A4: RUN 2 - night session, 9 Sep. Arena ambient is FLAT from 85 us to 100 ms (3.3-3.5 counts = sensor pedestal, not light); first real signal above 100 ms, still only 10 counts at 200 ms vs THRESH_LO 80. No ambient ceiling below ~200 ms. CAVEAT: run on a lab 9V battery of unknown charge - the marker measured 2.4x dimmer than run 1 at matched geometry (same cap: fill/lobe/w-h reproduce to 3%, so all four LEDs are lit and it is drive current, not optics). ABSOLUTE exposures therefore carry an unknown scale factor; column S normalises it away. A DETECTION is a valid lower bound; a NON-detection is provisional and flagged battery-limited until re-checked on a known 9.0 V pack.
A5: INSTRUMENT: all run-2 rows use a FORCED VGA 640x480 ratio-1 readout window. The old auto-size rule (QVGA below a 60 px blob) introduced a step in sigma at the switch point - QVGA measured 35% higher sigma than VGA on an identical blob. Placement repeatability at 90 deg is 3.2% (1 sigma, n=3).
A6: ROWS 7-11 VOID: measured 2026-09-09 before the lens focus problem was found. The lens was focused near, so the blob hollows out and grows with distance, flattening the exposure curve and faking the range limit. Focus was corrected at the end of that session (at 5 m, same exposure: fill 0.73->1.46, area 571->316, diameter 27.0->20.0 px). Re-sweep from 1 m with focus locked. See PROTOCOL.md section 1. | B6: Angle (deg) | C6: Distance (m) | D6: Exposure (us) | E6: Peak | F6: Sat px | G6: Sensor area (px) | H6: npix | I6: blobs | J6: w/h | K6: Fill | L6: Lobe | M6: sigma_u (px) | N6: sigma_v (px) | O6: sigma_RMS (px) | P6: Detected? (Y/N) | Q6: area x d^2 (const if resolved) | R6: Notes | S6: Exp / exp(1 m) (battery-independent)
A7: XL | B7: 90 | C7: 1 | D7: 7140 | E7: 211.6 | F7: 0 | G7: 5535 | H7: 6690 | I7: 1 | J7: 0.97 | K7: 1.55 | L7: 0.029 | M7: 0.0344 | N7: 0.0408 | O7: =IF(OR(M7="",N7=""),"",SQRT(0.5*(M7^2+N7^2))) | P7: Y | Q7: =IF(OR(C7="",G7=""),"",G7*C7^2) | R7: VOID - OLD (NEAR) LENS FOCUS. | S7: =IF(OR(D7="",D7=""),"",D7/D7)
C8: 2 | D8: 17998 | E8: 209.2 | F8: 0 | G8: 4812 | H8: 5705 | I8: 1 | J8: 0.98 | K8: 1.51 | L8: 0.037 | M8: 0.0216 | N8: 0.0378 | O8: =IF(OR(M8="",N8=""),"",SQRT(0.5*(M8^2+N8^2))) | P8: Y | Q8: =IF(OR(C8="",G8=""),"",G8*C8^2) | R8: VOID - OLD (NEAR) LENS FOCUS. QVGA 320x240 (blob ~55 px) - REDO IN VGA. sigma here is inflated ~35% by the window mode (see row 9), so it is not comparable with the VGA rows. Exposure 3.42x for 2x distance. | S8: =IF(OR(D8="",D7=""),"",D8/D7)
C9: 3 | D9: 38887 | E9: 211.9 | F9: 0 | G9: 4741 | H9: 5485 | I9: 1 | J9: 0.99 | K9: 1.48 | L9: 0.029 | M9: 0.0292 | N9: 0.0466 | O9: =IF(OR(M9="",N9=""),"",SQRT(0.5*(M9^2+N9^2))) | P9: Y | Q9: =IF(OR(C9="",G9=""),"",G9*C9^2) | R9: VOID - OLD (NEAR) LENS FOCUS. | S9: =IF(OR(D9="",D7=""),"",D9/D7)
C10: 4 | D10: 68488 | E10: 212.9 | F10: 0 | G10: 4663 | H10: 5375 | I10: 1 | J10: 1 | K10: 1.47 | L10: 0.025 | M10: 0.0257 | N10: 0.022 | O10: =IF(OR(M10="",N10=""),"",SQRT(0.5*(M10^2+N10^2))) | P10: Y | Q10: =IF(OR(C10="",G10=""),"",G10*C10^2) | R10: VOID - OLD (NEAR) LENS FOCUS. | S10: =IF(OR(D10="",D7=""),"",D10/D7)
C11: 5 | D11: 104018 | E11: 212.5 | F11: 0 | G11: 4639 | H11: 5342 | I11: 1 | J11: 1 | K11: 1.47 | L11: 0.026 | M11: 0.0108 | N11: 0.0292 | O11: =IF(OR(M11="",N11=""),"",SQRT(0.5*(M11^2+N11^2))) | P11: Y | Q11: =IF(OR(C11="",G11=""),"",G11*C11^2) | R11: VOID - OLD (NEAR) LENS FOCUS. | S11: =IF(OR(D11="",D7=""),"",D11/D7)
C12: 6 | D12: 148983 | E12: 214.8 | F12: 0 | G12: 4625 | H12: 5323 | I12: 1 | J12: 1 | K12: 1.47 | L12: 0.026 | M12: 0.0254 | N12: 0.0354 | O12: =IF(OR(M12="",N12=""),"",SQRT(0.5*(M12^2+N12^2))) | P12: Y | Q12: =IF(OR(C12="",G12=""),"",G12*C12^2) | S12: =IF(OR(D12="",D7=""),"",D12/D7)
C13: 7 | D13: 196562 | E13: 214.6 | F13: 0 | G13: 4620 | H13: 5313 | I13: 1 | J13: 0.99 | K13: 1.46 | L13: 0.028 | M13: 0.019 | N13: 0.0568 | O13: =IF(OR(M13="",N13=""),"",SQRT(0.5*(M13^2+N13^2))) | P13: Y | Q13: =IF(OR(C13="",G13=""),"",G13*C13^2) | S13: =IF(OR(D13="",D7=""),"",D13/D7)
C14: 8 | D14: 249985 | E14: 211.1 | F14: 0 | G14: 4575 | H14: 5282 | I14: 2 | J14: 0.99 | K14: 1.47 | L14: 0.028 | M14: 0.016 | N14: 0.0225 | O14: =IF(OR(M14="",N14=""),"",SQRT(0.5*(M14^2+N14^2))) | P14: Y | Q14: =IF(OR(C14="",G14=""),"",G14*C14^2) | S14: =IF(OR(D14="",D7=""),"",D14/D7)
A15: RUN 3 RESULT. Power law over 2-8 m: n=1.906 (90 deg, rms resid 1.0%) and n=1.854 (0 deg, 2.2%). Anisotropy 90/0 = 1.95 +/- 0.08, NO distance trend. Exposure span 1-8 m = 35x (not 64x). n<2 IS INSTRUMENTAL, NOT THE LED: inverse square 16.00 -> 15.22 (partial resolution, PSF 76 px) -> 14.58 (vignetting) vs 13.89 measured, 5% residual. The marker slid from r=430 px to r=658 px off-axis as it came in, so RADIAL POSITION WAS CONFOUNDED WITH RANGE. Do NOT rank builds on the exponent - rank on col S at matched distance. 1 m departs the power law (n=1.33/1.38): the marker becomes RESOLVED, surface brightness is conserved, so peak grows slower than flux. Fit gives PSF 76.0 px, effective emitter 17.8 mm behind a 25 mm cap. | O15: =IF(OR(M15="",N15=""),"",SQRT(0.5*(M15^2+N15^2))) | Q15: =IF(OR(C15="",G15=""),"",G15*C15^2) | R15: unused - grid is 1-8 m
O16: =IF(OR(M16="",N16=""),"",SQRT(0.5*(M16^2+N16^2))) | Q16: =IF(OR(C16="",G16=""),"",G16*C16^2) | R16: unused - grid is 1-8 m
A17: XL | B17: 0 | C17: 1 | D17: 3782 | E17: 213.2 | F17: 0 | G17: 5635 | H17: 6815 | I17: 1 | J17: 0.99 | K17: 1.52 | L17: 0.032 | M17: 0.0296 | N17: 0.036 | O17: =IF(OR(M17="",N17=""),"",SQRT(0.5*(M17^2+N17^2))) | P17: Y | Q17: =IF(OR(C17="",G17=""),"",G17*C17^2) | S17: =IF(OR(D17="",D17=""),"",D17/D17)
C18: 2 | D18: 9860 | E18: 205.5 | F18: 0 | G18: 4811 | H18: 5697 | I18: 1 | J18: 0.99 | K18: 1.49 | L18: 0.028 | M18: 0.0237 | N18: 0.0286 | O18: =IF(OR(M18="",N18=""),"",SQRT(0.5*(M18^2+N18^2))) | P18: Y | Q18: =IF(OR(C18="",G18=""),"",G18*C18^2) | S18: =IF(OR(D18="",D17=""),"",D18/D17)
C19: 3 | D19: 20400 | E19: 212.1 | F19: 0 | G19: 4747 | H19: 5524 | I19: 1 | J19: 0.99 | K19: 1.48 | L19: 0.025 | M19: 0.0144 | N19: 0.0192 | O19: =IF(OR(M19="",N19=""),"",SQRT(0.5*(M19^2+N19^2))) | P19: Y | Q19: =IF(OR(C19="",G19=""),"",G19*C19^2) | S19: =IF(OR(D19="",D17=""),"",D19/D17)
C20: 4 | D20: 34998 | E20: 209.3 | F20: 0 | G20: 4624 | H20: 5346 | I20: 1 | J20: 1 | K20: 1.48 | L20: 0.02 | M20: 0.016 | N20: 0.0237 | O20: =IF(OR(M20="",N20=""),"",SQRT(0.5*(M20^2+N20^2))) | P20: Y | Q20: =IF(OR(C20="",G20=""),"",G20*C20^2) | S20: =IF(OR(D20="",D17=""),"",D20/D17)
C21: 5 | D21: 51446 | E21: 207.2 | F21: 0 | G21: 4529 | H21: 5229 | I21: 1 | J21: 0.98 | K21: 1.49 | L21: 0.024 | M21: 0.0248 | N21: 0.039 | O21: =IF(OR(M21="",N21=""),"",SQRT(0.5*(M21^2+N21^2))) | P21: Y | Q21: =IF(OR(C21="",G21=""),"",G21*C21^2) | S21: =IF(OR(D21="",D17=""),"",D21/D17)
C22: 6 | D22: 71995 | E22: 209.9 | F22: 0 | G22: 4523 | H22: 5208 | I22: 1 | J22: 0.99 | K22: 1.49 | L22: 0.023 | M22: 0.0333 | N22: 0.0345 | O22: =IF(OR(M22="",N22=""),"",SQRT(0.5*(M22^2+N22^2))) | P22: Y | Q22: =IF(OR(C22="",G22=""),"",G22*C22^2) | S22: =IF(OR(D22="",D17=""),"",D22/D17)
C23: 7 | D23: 99216 | E23: 213.1 | F23: 0 | G23: 4555 | H23: 5235 | I23: 1 | J23: 0.99 | K23: 1.48 | L23: 0.021 | M23: 0.0134 | N23: 0.0203 | O23: =IF(OR(M23="",N23=""),"",SQRT(0.5*(M23^2+N23^2))) | P23: Y | Q23: =IF(OR(C23="",G23=""),"",G23*C23^2) | S23: =IF(OR(D23="",D17=""),"",D23/D17)
C24: 8 | D24: 131282 | E24: 213.6 | F24: 0 | G24: 4530 | H24: 5193 | I24: 3 | J24: 1 | K24: 1.47 | L24: 0.025 | M24: 0.0321 | N24: 0.0352 | O24: =IF(OR(M24="",N24=""),"",SQRT(0.5*(M24^2+N24^2))) | P24: Y | Q24: =IF(OR(C24="",G24=""),"",G24*C24^2) | R24: RUN 3 corridor. blobs=3. DRIFT CHECK: repeated at end of session -> 126458 us vs 131282 us (-3.7%, within the 3.2% placement repeatability). NO battery droop; the fitted exponent is real. | S24: =IF(OR(D24="",D17=""),"",D24/D17)
O25: =IF(OR(M25="",N25=""),"",SQRT(0.5*(M25^2+N25^2))) | Q25: =IF(OR(C25="",G25=""),"",G25*C25^2) | R25: unused - grid is 1-8 m
O26: =IF(OR(M26="",N26=""),"",SQRT(0.5*(M26^2+N26^2))) | Q26: =IF(OR(C26="",G26=""),"",G26*C26^2) | R26: unused - grid is 1-8 m
A27: Everlight | B27: 90 | C27: 1 | O27: =IF(OR(M27="",N27=""),"",SQRT(0.5*(M27^2+N27^2))) | Q27: =IF(OR(C27="",G27=""),"",G27*C27^2) | S27: =IF(OR(D27="",D27=""),"",D27/D27)
C28: 2 | O28: =IF(OR(M28="",N28=""),"",SQRT(0.5*(M28^2+N28^2))) | Q28: =IF(OR(C28="",G28=""),"",G28*C28^2) | S28: =IF(OR(D28="",D27=""),"",D28/D27)
C29: 3 | O29: =IF(OR(M29="",N29=""),"",SQRT(0.5*(M29^2+N29^2))) | Q29: =IF(OR(C29="",G29=""),"",G29*C29^2) | S29: =IF(OR(D29="",D27=""),"",D29/D27)
C30: 4 | O30: =IF(OR(M30="",N30=""),"",SQRT(0.5*(M30^2+N30^2))) | Q30: =IF(OR(C30="",G30=""),"",G30*C30^2) | S30: =IF(OR(D30="",D27=""),"",D30/D27)
C31: 5 | O31: =IF(OR(M31="",N31=""),"",SQRT(0.5*(M31^2+N31^2))) | Q31: =IF(OR(C31="",G31=""),"",G31*C31^2) | S31: =IF(OR(D31="",D27=""),"",D31/D27)
C32: 6 | O32: =IF(OR(M32="",N32=""),"",SQRT(0.5*(M32^2+N32^2))) | Q32: =IF(OR(C32="",G32=""),"",G32*C32^2) | S32: =IF(OR(D32="",D27=""),"",D32/D27)
C33: 7 | O33: =IF(OR(M33="",N33=""),"",SQRT(0.5*(M33^2+N33^2))) | Q33: =IF(OR(C33="",G33=""),"",G33*C33^2) | S33: =IF(OR(D33="",D27=""),"",D33/D27)
C34: 8 | O34: =IF(OR(M34="",N34=""),"",SQRT(0.5*(M34^2+N34^2))) | Q34: =IF(OR(C34="",G34=""),"",G34*C34^2) | S34: =IF(OR(D34="",D27=""),"",D34/D27)
O35: =IF(OR(M35="",N35=""),"",SQRT(0.5*(M35^2+N35^2))) | Q35: =IF(OR(C35="",G35=""),"",G35*C35^2) | R35: unused - grid is 1-8 m
O36: =IF(OR(M36="",N36=""),"",SQRT(0.5*(M36^2+N36^2))) | Q36: =IF(OR(C36="",G36=""),"",G36*C36^2) | R36: unused - grid is 1-8 m
A37: Everlight | B37: 0 | C37: 1 | O37: =IF(OR(M37="",N37=""),"",SQRT(0.5*(M37^2+N37^2))) | Q37: =IF(OR(C37="",G37=""),"",G37*C37^2) | S37: =IF(OR(D37="",D37=""),"",D37/D37)
C38: 2 | O38: =IF(OR(M38="",N38=""),"",SQRT(0.5*(M38^2+N38^2))) | Q38: =IF(OR(C38="",G38=""),"",G38*C38^2) | S38: =IF(OR(D38="",D37=""),"",D38/D37)
C39: 3 | O39: =IF(OR(M39="",N39=""),"",SQRT(0.5*(M39^2+N39^2))) | Q39: =IF(OR(C39="",G39=""),"",G39*C39^2) | S39: =IF(OR(D39="",D37=""),"",D39/D37)
C40: 4 | O40: =IF(OR(M40="",N40=""),"",SQRT(0.5*(M40^2+N40^2))) | Q40: =IF(OR(C40="",G40=""),"",G40*C40^2) | S40: =IF(OR(D40="",D37=""),"",D40/D37)
...

Sheet C_Range_run1
A1: TEST C - Range, at 0 deg and 90 deg
A2: FROZEN - run 1, 20 Feb daylight session. Superseded: taken on a different (later failing) battery, so the ABSOLUTE exposures are not comparable with run 2. Shape metrics (fill/lobe/w-h) and sigma ARE comparable, being measured at matched peak. Distance grid was 0.7/1.5/2.5...9.5 m.
A4: Arena ambient ceiling today: ~14.5 ms in frame, ~40 ms away from the right-hand windows (overcast 16:25).
A6: LED Type | B6: Angle (deg) | C6: Distance (m) | D6: Exposure (us) | E6: Peak | F6: Sat px | G6: Sensor area (px) | H6: npix | I6: blobs | J6: w/h | K6: Fill | L6: Lobe | M6: sigma_u (px) | N6: sigma_v (px) | O6: sigma_RMS (px) | P6: Detected? (Y/N) | Q6: area x d^2 (const if resolved) | R6: Notes
A7: XL | B7: 90 | C7: 0.7 | D7: 1997 | E7: 210.2 | F7: 0 | G7: 4999 | H7: 6098 | I7: 1 | J7: 0.9 | K7: 1.51 | L7: 0.115 | M7: 0.0125 | N7: 0.024 | O7: =IF(OR(M7="",N7=""),"",SQRT(0.5*(M7^2+N7^2))) | P7: Y | Q7: =IF(OR(C7="",G7=""),"",G7*C7^2) | R7: VGA 640x480 window (blob ~103 px). QVGA compresses at this blob size - black-level depression when the marker fills >10% of frame.
C8: 1.5 | D8: 3187 | E8: 205.2 | F8: 0 | G8: 1732 | H8: 2188 | I8: 1 | J8: 0.92 | K8: 1.56 | L8: 0.074 | M8: 0.0108 | N8: 0.0213 | O8: =IF(OR(M8="",N8=""),"",SQRT(0.5*(M8^2+N8^2))) | P8: Y | Q8: =IF(OR(C8="",G8=""),"",G8*C8^2)
C9: 2.5 | D9: 9760 | E9: 204.8 | F9: 0 | G9: 1267 | H9: 1441 | I9: 1 | J9: 0.97 | K9: 1.19 | L9: 0.065 | M9: 0.0163 | N9: 0.0219 | O9: =IF(OR(M9="",N9=""),"",SQRT(0.5*(M9^2+N9^2))) | P9: Y | Q9: =IF(OR(C9="",G9=""),"",G9*C9^2) | R9: Exposure now scaling as d^2 (3.06x for 1.67x distance) - the marker has gone point-like between 1.5 and 2.5 m.
C10: 3.5 | O10: =IF(OR(M10="",N10=""),"",SQRT(0.5*(M10^2+N10^2))) | P10: N | Q10: =IF(OR(C10="",G10=""),"",G10*C10^2) | R10: AMBIENT-LIMITED, not marker-limited. Targeting ran to 101702 us (7x the ~14.5 ms arena ceiling) and locked onto window light: blobs 3, w/h 1.59, lobe 0.787 - not a marker. XL at 90 deg is unusable beyond ~2.5-3 m under this afternoon's overcast. Re-measure at night. NOT DETECTED
C11: 4.5 | O11: =IF(OR(M11="",N11=""),"",SQRT(0.5*(M11^2+N11^2))) | Q11: =IF(OR(C11="",G11=""),"",G11*C11^2)
C12: 5.5 | O12: =IF(OR(M12="",N12=""),"",SQRT(0.5*(M12^2+N12^2))) | Q12: =IF(OR(C12="",G12=""),"",G12*C12^2)
C13: 6.5 | O13: =IF(OR(M13="",N13=""),"",SQRT(0.5*(M13^2+N13^2))) | Q13: =IF(OR(C13="",G13=""),"",G13*C13^2)
C14: 7.5 | O14: =IF(OR(M14="",N14=""),"",SQRT(0.5*(M14^2+N14^2))) | Q14: =IF(OR(C14="",G14=""),"",G14*C14^2)
C15: 8.5 | O15: =IF(OR(M15="",N15=""),"",SQRT(0.5*(M15^2+N15^2))) | Q15: =IF(OR(C15="",G15=""),"",G15*C15^2)
C16: 9.5 | O16: =IF(OR(M16="",N16=""),"",SQRT(0.5*(M16^2+N16^2))) | Q16: =IF(OR(C16="",G16=""),"",G16*C16^2)
A17: XL | B17: 0 | C17: 0.7 | O17: =IF(OR(M17="",N17=""),"",SQRT(0.5*(M17^2+N17^2))) | Q17: =IF(OR(C17="",G17=""),"",G17*C17^2)
C18: 1.5 | O18: =IF(OR(M18="",N18=""),"",SQRT(0.5*(M18^2+N18^2))) | Q18: =IF(OR(C18="",G18=""),"",G18*C18^2)
C19: 2.5 | O19: =IF(OR(M19="",N19=""),"",SQRT(0.5*(M19^2+N19^2))) | Q19: =IF(OR(C19="",G19=""),"",G19*C19^2)
C20: 3.5 | O20: =IF(OR(M20="",N20=""),"",SQRT(0.5*(M20^2+N20^2))) | Q20: =IF(OR(C20="",G20=""),"",G20*C20^2)
C21: 4.5 | O21: =IF(OR(M21="",N21=""),"",SQRT(0.5*(M21^2+N21^2))) | Q21: =IF(OR(C21="",G21=""),"",G21*C21^2)
C22: 5.5 | O22: =IF(OR(M22="",N22=""),"",SQRT(0.5*(M22^2+N22^2))) | Q22: =IF(OR(C22="",G22=""),"",G22*C22^2)
C23: 6.5 | O23: =IF(OR(M23="",N23=""),"",SQRT(0.5*(M23^2+N23^2))) | Q23: =IF(OR(C23="",G23=""),"",G23*C23^2)
C24: 7.5 | O24: =IF(OR(M24="",N24=""),"",SQRT(0.5*(M24^2+N24^2))) | Q24: =IF(OR(C24="",G24=""),"",G24*C24^2)
C25: 8.5 | O25: =IF(OR(M25="",N25=""),"",SQRT(0.5*(M25^2+N25^2))) | Q25: =IF(OR(C25="",G25=""),"",G25*C25^2)
C26: 9.5 | O26: =IF(OR(M26="",N26=""),"",SQRT(0.5*(M26^2+N26^2))) | Q26: =IF(OR(C26="",G26=""),"",G26*C26^2)
A27: Everlight | B27: 90 | C27: 0.7 | O27: =IF(OR(M27="",N27=""),"",SQRT(0.5*(M27^2+N27^2))) | Q27: =IF(OR(C27="",G27=""),"",G27*C27^2)
C28: 1.5 | O28: =IF(OR(M28="",N28=""),"",SQRT(0.5*(M28^2+N28^2))) | Q28: =IF(OR(C28="",G28=""),"",G28*C28^2)
C29: 2.5 | O29: =IF(OR(M29="",N29=""),"",SQRT(0.5*(M29^2+N29^2))) | Q29: =IF(OR(C29="",G29=""),"",G29*C29^2)
C30: 3.5 | O30: =IF(OR(M30="",N30=""),"",SQRT(0.5*(M30^2+N30^2))) | Q30: =IF(OR(C30="",G30=""),"",G30*C30^2)
C31: 4.5 | O31: =IF(OR(M31="",N31=""),"",SQRT(0.5*(M31^2+N31^2))) | Q31: =IF(OR(C31="",G31=""),"",G31*C31^2)
C32: 5.5 | O32: =IF(OR(M32="",N32=""),"",SQRT(0.5*(M32^2+N32^2))) | Q32: =IF(OR(C32="",G32=""),"",G32*C32^2)
C33: 6.5 | O33: =IF(OR(M33="",N33=""),"",SQRT(0.5*(M33^2+N33^2))) | Q33: =IF(OR(C33="",G33=""),"",G33*C33^2)
C34: 7.5 | O34: =IF(OR(M34="",N34=""),"",SQRT(0.5*(M34^2+N34^2))) | Q34: =IF(OR(C34="",G34=""),"",G34*C34^2)
C35: 8.5 | O35: =IF(OR(M35="",N35=""),"",SQRT(0.5*(M35^2+N35^2))) | Q35: =IF(OR(C35="",G35=""),"",G35*C35^2)
C36: 9.5 | O36: =IF(OR(M36="",N36=""),"",SQRT(0.5*(M36^2+N36^2))) | Q36: =IF(OR(C36="",G36=""),"",G36*C36^2)
A37: Everlight | B37: 0 | C37: 0.7 | O37: =IF(OR(M37="",N37=""),"",SQRT(0.5*(M37^2+N37^2))) | Q37: =IF(OR(C37="",G37=""),"",G37*C37^2)
C38: 1.5 | O38: =IF(OR(M38="",N38=""),"",SQRT(0.5*(M38^2+N38^2))) | Q38: =IF(OR(C38="",G38=""),"",G38*C38^2)
C39: 2.5 | O39: =IF(OR(M39="",N39=""),"",SQRT(0.5*(M39^2+N39^2))) | Q39: =IF(OR(C39="",G39=""),"",G39*C39^2)
C40: 3.5 | O40: =IF(OR(M40="",N40=""),"",SQRT(0.5*(M40^2+N40^2))) | Q40: =IF(OR(C40="",G40=""),"",G40*C40^2)
C41: 4.5 | O41: =IF(OR(M41="",N41=""),"",SQRT(0.5*(M41^2+N41^2))) | Q41: =IF(OR(C41="",G41=""),"",G41*C41^2)
C42: 5.5 | O42: =IF(OR(M42="",N42=""),"",SQRT(0.5*(M42^2+N42^2))) | Q42: =IF(OR(C42="",G42=""),"",G42*C42^2)
...

Sheet E_Strobe
A1: TEST E - Pulsed / strobed drive
A2: Blue on yellow = fill in. Black = calculated. Everything on A_Bench was measured DC; this is the operating condition the strobed PCB will actually run in. Rolling shutter: each row starts integrating 21.3 us after the one above it, so a pulse shorter than the sweep across the marker lights only PART of it and drags the centroid.
A3: Row time (us) | B3: 21.3 | C3: one sensor row. Measured: exposure quantises to this
A4: Marker row span | B4: 30 | C4: marker height in sensor rows at the working distance
A5: Min pulse (ms) | B5: =IF(OR(B3="",B4="",B6=""),"",(B4*B3+B6)/1000) | C5: =(row span x row time + exposure). Below this the marker is only partly lit
A6: Exposure (us) | C6: the exposure Test A landed for this build
A8: E1 - PULSE WIDTH SWEEP (one build, fixed duty and exposure. Where does the banding start?)
A9: LED Type | B9: Build | C9: Pulse width (ms) | D9: Period (ms) | E9: Duty (%) | F9: Peak I (mA) | G9: Exposure (us) | H9: Peak (0-255) | I9: Sensor area (px) | J9: blobs | K9: w/h | L9: Fill (centre/rim) | M9: Banded? (Y/N) | N9: Centroid shift vs DC (px) | O9: Uniform? | P9: Notes
C10: 0.25 | O10: =IF(OR(M10="",L10=""),"",IF(AND(UPPER(M10)="N",L10>=0.85),"pass","FAIL"))
C11: 0.5 | O11: =IF(OR(M11="",L11=""),"",IF(AND(UPPER(M11)="N",L11>=0.85),"pass","FAIL"))
C12: 1 | O12: =IF(OR(M12="",L12=""),"",IF(AND(UPPER(M12)="N",L12>=0.85),"pass","FAIL"))
C13: 2 | O13: =IF(OR(M13="",L13=""),"",IF(AND(UPPER(M13)="N",L13>=0.85),"pass","FAIL"))
C14: 4 | O14: =IF(OR(M14="",L14=""),"",IF(AND(UPPER(M14)="N",L14>=0.85),"pass","FAIL"))
C15: 8 | O15: =IF(OR(M15="",L15=""),"",IF(AND(UPPER(M15)="N",L15>=0.85),"pass","FAIL"))
C16: 16 | O16: =IF(OR(M16="",L16=""),"",IF(AND(UPPER(M16)="N",L16>=0.85),"pass","FAIL"))
A18: E2 - OPERATING POINT vs DC (does pulsing change sigma, fill or the centroid?)
A19: LED Type | B19: Build | C19: Peak I (mA) | D19: Duty (%) | E19: Pulse (ms) | F19: Exposure (us) | G19: Peak (0-255) | H19: Sensor area (px) | I19: blobs | J19: w/h | K19: Fill | L19: sigma_u (px) | M19: sigma_v (px) | N19: sigma_RMS (px) | O19: DC sigma_RMS | P19: Pulsed / DC | Q19: Notes
A20: Kingbright | B20: 25 mm | N20: =IF(OR(L20="",M20=""),"",SQRT(0.5*(L20^2+M20^2))) | O20: =IFERROR(A_Bench!R16,"") | P20: =IF(OR(N20="",O20="",O20=0),"",N20/O20)
A21: Vishay | B21: 25 mm | N21: =IF(OR(L21="",M21=""),"",SQRT(0.5*(L21^2+M21^2))) | O21: =IFERROR(A_Bench!R13,"") | P21: =IF(OR(N21="",O21="",O21=0),"",N21/O21)
A22: Kingbright | B22: 20 mm | N22: =IF(OR(L22="",M22=""),"",SQRT(0.5*(L22^2+M22^2))) | O22: =IFERROR(A_Bench!R12,"") | P22: =IF(OR(N22="",O22="",O22=0),"",N22/O22)
A23: XL | B23: 25 mm | N23: =IF(OR(L23="",M23=""),"",SQRT(0.5*(L23^2+M23^2))) | O23: =IFERROR(A_Bench!R15,"") | P23: =IF(OR(N23="",O23="",O23=0),"",N23/O23)
A25: E3 - TIMING RECOVERY (how precisely can a strobe edge be read off the rolling shutter?)
A26: Catch a frame containing an ON->OFF or OFF->ON transition. The boundary row is when the edge happened. Transition width is how many rows it takes to go from lit to dark - that width, times the row time, IS your timing resolution.
A27: Trial | B27: Edge (ON->OFF / OFF->ON) | C27: Boundary row | D27: Transition width (rows) | E27: Timing resolution (us) | F27: Notes
A28: 1 | E28: =IF(OR(D28="",$B$3=""),"",D28*$B$3)
A29: 2 | E29: =IF(OR(D29="",$B$3=""),"",D29*$B$3)
A30: 3 | E30: =IF(OR(D30="",$B$3=""),"",D30*$B$3)
A31: 4 | E31: =IF(OR(D31="",$B$3=""),"",D31*$B$3)
A32: 5 | E32: =IF(OR(D32="",$B$3=""),"",D32*$B$3)
A33: 6 | E33: =IF(OR(D33="",$B$3=""),"",D33*$B$3)
A34: 7 | E34: =IF(OR(D34="",$B$3=""),"",D34*$B$3)
A35: 8 | E35: =IF(OR(D35="",$B$3=""),"",D35*$B$3)
A36: 9 | E36: =IF(OR(D36="",$B$3=""),"",D36*$B$3)
A37: 10 | E37: =IF(OR(D37="",$B$3=""),"",D37*$B$3)
D38: mean | E38: =IF(COUNT(E28:E37)=0,"",AVERAGE(E28:E37))
D39: SD | E39: =IFERROR(STDEV(E28:E37),"")
D40: wand err | E40: =IF(OR(E38="",$B$42="",$B$43=""),"",E38*$B$42*$B$43/1000000) | F40: px of reprojection error at the wand speed below
A42: Wand speed (m/s) | B42: 0.3
A43: Image scale (px/s per m/s) | B43: 1300 | C43: ~f_px/distance. PROVISIONAL until the intrinsics are calibrated
A44: Timing error budget (us) | B44: =IF(OR(B42="",B43="",B42=0,B43=0),"",0.1/(B42*B43)*1000000) | C44: how much timing error costs 0.1 px at that wand speed
...

Sheet F_Ambient
A1: TEST F - Ambient IR and threshold headroom
A2: Decides whether the long-exposure strobe scheme (Test E, regime B) is available. A long exposure collects a long dose of background. Raising THRESH_LO hides the background OFFSET but not its NOISE, and it does not recover the dynamic range the pedestal eats.
A4: F1 - BACKGROUND vs EXPOSURE (LEDs OFF, under the lighting you will actually calibrate in)
A5: Condition | B5: Exposure (us, requested) | C5: Exposure (us, actual) | D5: bg mean | E5: bg SD | F5: bg max | G5: Uniformity (max-min) | H5: Headroom (255-max) | I5: REFINE_FLOOR needed | J5: Usable? | K5: Notes
A6: as-is 2026-09-03 | B6: 100 | C6: 85 | D6: 3.6 | E6: 0.5 | F6: 4 | G6: 1 | H6: =IF(F6="","",255-F6) | I6: =IF(OR(D6="",E6=""),"",D6+3*E6) | J6: =IF(F6="","",IF(F6<40,"ok",IF(F6<80,"marginal","FLOODED"))) | K6: flat with exposure - this is the sensor black level, not light
A7: as-is 2026-09-03 | B7: 500 | C7: 493 | D7: 3.6 | E7: 0.5 | F7: 4 | G7: 1 | H7: =IF(F7="","",255-F7) | I7: =IF(OR(D7="",E7=""),"",D7+3*E7) | J7: =IF(F7="","",IF(F7<40,"ok",IF(F7<80,"marginal","FLOODED")))
A8: as-is 2026-09-03 | B8: 1000 | C8: 986 | D8: 3.6 | E8: 0.5 | F8: 4 | G8: 2 | H8: =IF(F8="","",255-F8) | I8: =IF(OR(D8="",E8=""),"",D8+3*E8) | J8: =IF(F8="","",IF(F8<40,"ok",IF(F8<80,"marginal","FLOODED")))
A9: as-is 2026-09-03 | B9: 2000 | C9: 1994 | D9: 3.6 | E9: 0.5 | F9: 4 | G9: 1 | H9: =IF(F9="","",255-F9) | I9: =IF(OR(D9="",E9=""),"",D9+3*E9) | J9: =IF(F9="","",IF(F9<40,"ok",IF(F9<80,"marginal","FLOODED")))
A10: as-is 2026-09-03 | B10: 5000 | C10: 4997 | D10: 3.5 | E10: 0.5 | F10: 4 | G10: 2 | H10: =IF(F10="","",255-F10) | I10: =IF(OR(D10="",E10=""),"",D10+3*E10) | J10: =IF(F10="","",IF(F10<40,"ok",IF(F10<80,"marginal","FLOODED")))
A11: as-is 2026-09-03 | B11: 10000 | C11: 9995 | D11: 3.5 | E11: 0.5 | F11: 4 | G11: 2 | H11: =IF(F11="","",255-F11) | I11: =IF(OR(D11="",E11=""),"",D11+3*E11) | J11: =IF(F11="","",IF(F11<40,"ok",IF(F11<80,"marginal","FLOODED")))
